<ns0:test-suite xmlns:ns0="urn:model.allure.qatools.yandex.ru" start="1588234684116" stop="1588234684179">
  <name>test_plugin_allure</name>
  <labels/>
  <test-cases>
    <test-case start="1588234684116" status="passed" stop="1588234684118">
      <name>TestAllurePlugin.test_with_an_issue</name>
      <attachments/>
      <labels>
        <label name="story" value="My story"/>
        <label name="feature" value="My Feature"/>
        <label name="issue" value="https://app.clubhouse.io/dataiku/story/46470"/>
        <label name="issue" value="https://app.clubhouse.io/dataiku/story/28092"/>
        <label name="severity" value="normal"/>
        <label name="thread" value="22874-MainThread"/>
        <label name="host" value="MBP-Dataiku-KRemy.local"/>
        <label name="framework" value="pytest"/>
        <label name="language" value="cpython2"/>
      </labels>
      <steps/>
    </test-case>
    <test-case start="1588234684120" status="passed" stop="1588234684121">
      <name>TestAllurePlugin.test_without_issue</name>
      <attachments/>
      <labels>
        <label name="severity" value="normal"/>
        <label name="thread" value="22874-MainThread"/>
        <label name="host" value="MBP-Dataiku-KRemy.local"/>
        <label name="framework" value="pytest"/>
        <label name="language" value="cpython2"/>
      </labels>
      <steps/>
    </test-case>
    <test-case start="1588234684122" status="failed" stop="1588234684172">
      <name>TestAllurePlugin.test_that_fail_without_issue</name>
      <failure>
        <message>AssertionError: assert False</message>
        <stack-trace>self = &lt;test_plugin_allure.TestAllurePlugin object at 0x10a33c450&gt;

    def test_that_fail_without_issue(self):
&gt;       assert False
E       assert False

dev/test_plugin_allure.py:17: AssertionError</stack-trace>
      </failure>
      <attachments/>
      <labels>
        <label name="severity" value="normal"/>
        <label name="thread" value="22874-MainThread"/>
        <label name="host" value="MBP-Dataiku-KRemy.local"/>
        <label name="framework" value="pytest"/>
        <label name="language" value="cpython2"/>
      </labels>
      <steps/>
    </test-case>
    <test-case start="1588234684175" status="failed" stop="1588234684179">
      <name>TestAllurePlugin.test_that_fail_with_issue</name>
      <failure>
        <message>AssertionError: assert False</message>
        <stack-trace>self = &lt;test_plugin_allure.TestAllurePlugin object at 0x10a36ed10&gt;

    @allure.issue("https://app.clubhouse.io/dataiku/story/47133")
    def test_that_fail_with_issue(self):
&gt;       assert False
E       assert False

dev/test_plugin_allure.py:21: AssertionError</stack-trace>
      </failure>
      <attachments/>
      <labels>
        <label name="issue" value="https://app.clubhouse.io/dataiku/story/47133"/>
        <label name="severity" value="normal"/>
        <label name="thread" value="22874-MainThread"/>
        <label name="host" value="MBP-Dataiku-KRemy.local"/>
        <label name="framework" value="pytest"/>
        <label name="language" value="cpython2"/>
      </labels>
      <steps/>
    </test-case>
  </test-cases>
</ns0:test-suite>
